  0%|                                                                  | 0/2 [00:00<?, ?it/s]We detected that you are passing `past_key_values` as a tuple and this is deprecated and will be removed in v4.43. Please use an appropriate `Cache` class (https://huggingface.co/docs/transformers/v4.41.3/en/internal/generation_utils#transformers.Cache)
Traceback (most recent call last):
  File "/home/jingbo/anaconda3/envs/unlearning/lib/python3.9/site-packages/peft/peft_model.py", line 619, in __getattr__
    return super().__getattr__(name)  # defer to nn.Module's logic
  File "/home/jingbo/anaconda3/envs/unlearning/lib/python3.9/site-packages/torch/nn/modules/module.py", line 1709, in __getattr__
    raise AttributeError(f"'{type(self).__name__}' object has no attribute '{name}'")
AttributeError: 'PeftModelForCausalLM' object has no attribute 'get_device'
During handling of the above exception, another exception occurred:
Traceback (most recent call last):
  File "/home/jingbo/anaconda3/envs/unlearning/lib/python3.9/site-packages/peft/tuners/lora/model.py", line 330, in __getattr__
    return super().__getattr__(name)  # defer to nn.Module's logic
  File "/home/jingbo/anaconda3/envs/unlearning/lib/python3.9/site-packages/torch/nn/modules/module.py", line 1709, in __getattr__
    raise AttributeError(f"'{type(self).__name__}' object has no attribute '{name}'")
AttributeError: 'LoraModel' object has no attribute 'get_device'
During handling of the above exception, another exception occurred:
Traceback (most recent call last):
  File "/home/jingbo/KVMemory/finetune_connect.py", line 93, in <module>
    main()
  File "/home/jingbo/KVMemory/finetune_connect.py", line 81, in main
    trainer.train()
  File "/home/jingbo/anaconda3/envs/unlearning/lib/python3.9/site-packages/transformers/trainer.py", line 1938, in train
    return inner_training_loop(
  File "/home/jingbo/anaconda3/envs/unlearning/lib/python3.9/site-packages/transformers/trainer.py", line 2274, in _inner_training_loop
    tr_loss_step = self.training_step(model, inputs)
  File "/home/jingbo/anaconda3/envs/unlearning/lib/python3.9/site-packages/transformers/trainer.py", line 3313, in training_step
    loss = self.compute_loss(model, inputs)
  File "/home/jingbo/KVMemory/src/training/trainer.py", line 95, in compute_loss
    outputs = self.model(input_ids=remaining_ids_batch, attention_mask=attention_mask, labels = remaining_ids_batch, past_key_values=split_past_key_values, use_cache=True)
  File "/home/jingbo/anaconda3/envs/unlearning/lib/python3.9/site-packages/torch/nn/modules/module.py", line 1532, in _wrapped_call_impl
    return self._call_impl(*args, **kwargs)
  File "/home/jingbo/anaconda3/envs/unlearning/lib/python3.9/site-packages/torch/nn/modules/module.py", line 1541, in _call_impl
    return forward_call(*args, **kwargs)
  File "/home/jingbo/KVMemory/src/model/model.py", line 33, in forward
    kv_s = generate_kv_with_connect(self.base_model, torch.tensor([[1]]))
  File "/home/jingbo/KVMemory/src/utils/cache.py", line 14, in generate_kv_with_connect
    input_ids = input_ids.to(model.get_device())
  File "/home/jingbo/anaconda3/envs/unlearning/lib/python3.9/site-packages/peft/peft_model.py", line 621, in __getattr__
    return getattr(self.base_model, name)
  File "/home/jingbo/anaconda3/envs/unlearning/lib/python3.9/site-packages/peft/tuners/lora/model.py", line 332, in __getattr__
    return getattr(self.model, name)
  File "/home/jingbo/anaconda3/envs/unlearning/lib/python3.9/site-packages/torch/nn/modules/module.py", line 1709, in __getattr__
    raise AttributeError(f"'{type(self).__name__}' object has no attribute '{name}'")
AttributeError: 'LlamaForCausalLM' object has no attribute 'get_device'
[rank0]: Traceback (most recent call last):
[rank0]:   File "/home/jingbo/anaconda3/envs/unlearning/lib/python3.9/site-packages/peft/peft_model.py", line 619, in __getattr__
[rank0]:     return super().__getattr__(name)  # defer to nn.Module's logic
[rank0]:   File "/home/jingbo/anaconda3/envs/unlearning/lib/python3.9/site-packages/torch/nn/modules/module.py", line 1709, in __getattr__
[rank0]:     raise AttributeError(f"'{type(self).__name__}' object has no attribute '{name}'")
[rank0]: AttributeError: 'PeftModelForCausalLM' object has no attribute 'get_device'
[rank0]: During handling of the above exception, another exception occurred:
[rank0]: Traceback (most recent call last):
[rank0]:   File "/home/jingbo/anaconda3/envs/unlearning/lib/python3.9/site-packages/peft/tuners/lora/model.py", line 330, in __getattr__
[rank0]:     return super().__getattr__(name)  # defer to nn.Module's logic
[rank0]:   File "/home/jingbo/anaconda3/envs/unlearning/lib/python3.9/site-packages/torch/nn/modules/module.py", line 1709, in __getattr__
[rank0]:     raise AttributeError(f"'{type(self).__name__}' object has no attribute '{name}'")
[rank0]: AttributeError: 'LoraModel' object has no attribute 'get_device'
[rank0]: During handling of the above exception, another exception occurred:
[rank0]: Traceback (most recent call last):
[rank0]:   File "/home/jingbo/KVMemory/finetune_connect.py", line 93, in <module>
[rank0]:     main()
[rank0]:   File "/home/jingbo/KVMemory/finetune_connect.py", line 81, in main
[rank0]:     trainer.train()
[rank0]:   File "/home/jingbo/anaconda3/envs/unlearning/lib/python3.9/site-packages/transformers/trainer.py", line 1938, in train
[rank0]:     return inner_training_loop(
[rank0]:   File "/home/jingbo/anaconda3/envs/unlearning/lib/python3.9/site-packages/transformers/trainer.py", line 2274, in _inner_training_loop
[rank0]:     tr_loss_step = self.training_step(model, inputs)
[rank0]:   File "/home/jingbo/anaconda3/envs/unlearning/lib/python3.9/site-packages/transformers/trainer.py", line 3313, in training_step
[rank0]:     loss = self.compute_loss(model, inputs)
[rank0]:   File "/home/jingbo/KVMemory/src/training/trainer.py", line 95, in compute_loss
[rank0]:     outputs = self.model(input_ids=remaining_ids_batch, attention_mask=attention_mask, labels = remaining_ids_batch, past_key_values=split_past_key_values, use_cache=True)
[rank0]:   File "/home/jingbo/anaconda3/envs/unlearning/lib/python3.9/site-packages/torch/nn/modules/module.py", line 1532, in _wrapped_call_impl
[rank0]:     return self._call_impl(*args, **kwargs)
[rank0]:   File "/home/jingbo/anaconda3/envs/unlearning/lib/python3.9/site-packages/torch/nn/modules/module.py", line 1541, in _call_impl
[rank0]:     return forward_call(*args, **kwargs)
[rank0]:   File "/home/jingbo/KVMemory/src/model/model.py", line 33, in forward
[rank0]:     kv_s = generate_kv_with_connect(self.base_model, torch.tensor([[1]]))
[rank0]:   File "/home/jingbo/KVMemory/src/utils/cache.py", line 14, in generate_kv_with_connect
[rank0]:     input_ids = input_ids.to(model.get_device())
[rank0]:   File "/home/jingbo/anaconda3/envs/unlearning/lib/python3.9/site-packages/peft/peft_model.py", line 621, in __getattr__
[rank0]:     return getattr(self.base_model, name)
[rank0]:   File "/home/jingbo/anaconda3/envs/unlearning/lib/python3.9/site-packages/peft/tuners/lora/model.py", line 332, in __getattr__
[rank0]:     return getattr(self.model, name)
[rank0]:   File "/home/jingbo/anaconda3/envs/unlearning/lib/python3.9/site-packages/torch/nn/modules/module.py", line 1709, in __getattr__
[rank0]:     raise AttributeError(f"'{type(self).__name__}' object has no attribute '{name}'")
[rank0]: AttributeError: 'LlamaForCausalLM' object has no attribute 'get_device'